<?xml version="1.0"?>

<robot name="robot_urdf" xmlns:xacro="http://www.ros.org/wiki/xacro">

  <xacro:include filename="$(find robot_urdf)/urdf/robot_urdf_gazebo.xacro" />
  
  <xacro:include filename="$(find robot_urdf)/urdf/robot_urdf_control.xacro" />
  
  <!-- Dummy link to fix root inertia warning -->
  <link name="base_footprint"/>

  <joint name="base_joint" type="fixed">
    <parent link="base_footprint"/>
    <child link="base_link"/>
    <origin xyz="0 0 0" rpy="0 0 0"/>
  </joint>

  <!-- Base Link -->
  <link name="base_link">
    <inertial>
      <origin xyz="-0.0028474 0.044831 0.17201" rpy="0 0 0" />
      <mass value="16.066" />
      <inertia ixx="0.78008" ixy="-0.00012591" ixz="-4.1689E-05"
               iyy="0.20279" iyz="-0.081775" izz="0.8623" />
    </inertial>
    <visual>
      <origin xyz="0 0 0" rpy="0 0 0" />
      <geometry>
        <mesh filename="package://robot_urdf/meshes/base_link.STL" />
      </geometry>
      <material name="">
        <color rgba="0.79216 0.81961 0.93333 1" />
      </material>
    </visual>
    <collision>
      <origin xyz="0 0 0" rpy="0 0 0" />
      <geometry>
        <mesh filename="package://robot_urdf/meshes/base_link.STL" />
      </geometry>
    </collision>
  </link>

  <link
    name="caster_link_left">
    <inertial>
      <origin
        xyz="-0.00033745 -0.03325 0.0092752"
        rpy="0 0 0" />
      <mass
        value="0.026905" />
      <inertia
        ixx="1.7873E-05"
        ixy="-1.9068E-07"
        ixz="-7.6425E-08"
        iyy="1.3196E-05"
        iyz="5.2414E-06"
        izz="1.997E-05" />
    </inertial>
    <visual>
      <origin
        xyz="0 0 0"
        rpy="0 0 0" />
      <geometry>
        <mesh
          filename="package://robot_urdf/meshes/caster_link_left.STL" />
      </geometry>
      <material
        name="">
        <color
          rgba="0.79216 0.81961 0.93333 1" />
      </material>
    </visual>
    <collision>
      <origin
        xyz="0 0 0"
        rpy="0 0 0" />
      <geometry>
        <mesh
          filename="package://robot_urdf/meshes/caster_link_left.STL" />
      </geometry>
    </collision>
  </link>
  <joint
    name="caster_joint_left"
    type="fixed">
    <origin
      xyz="0.072155 0.26812 0.1075"
      rpy="1.5708 0 0" />
    <parent
      link="base_link" />
    <child
      link="caster_link_left" />
    <axis
      xyz="0 -1 0" />
  </joint>
  <link
    name="caster_wheel_link_left">
    <inertial>
      <origin
        xyz="-0.015989 0 -0.0005817"
        rpy="0 0 0" />
      <mass
        value="0.10698" />
      <inertia
        ixx="8.1432E-05"
        ixy="6.6857E-21"
        ixz="1.3043E-06"
        iyy="4.558E-05"
        iyz="-2.135E-21"
        izz="4.5627E-05" />
    </inertial>
    <visual>
      <origin
        xyz="0 0 0"
        rpy="0 0 0" />
      <geometry>
        <mesh
          filename="package://robot_urdf/meshes/caster_wheel_link_left.STL" />
      </geometry>
      <material
        name="">
        <color
          rgba="0.79216 0.81961 0.93333 1" />
      </material>
    </visual>
    <collision>
      <origin
        xyz="0 0 0"
        rpy="0 0 0" />
      <geometry>
        <mesh
          filename="package://robot_urdf/meshes/caster_wheel_link_left.STL" />
      </geometry>
    </collision>
  </link>
  <joint
    name="caster_wheel_joint_left"
    type="continuous">
    <origin
      xyz="0.015083 -0.0675 0.025488"
      rpy="0 0 0" />
    <parent
      link="caster_link_left" />
    <child
      link="caster_wheel_link_left" />
    <axis
      xyz="0.99934 0 0.036356" />
  </joint>
  <link
    name="caster_link_right">
    <inertial>
      <origin
        xyz="0.0010261 -0.03325 0.0092245"
        rpy="0 0 0" />
      <mass
        value="0.026905" />
      <inertia
        ixx="1.7895E-05"
        ixy="5.7987E-07"
        ixz="2.3113E-07"
        iyy="1.3196E-05"
        iyz="5.2127E-06"
        izz="1.9948E-05" />
    </inertial>
    <visual>
      <origin
        xyz="0 0 0"
        rpy="0 0 0" />
      <geometry>
        <mesh
          filename="package://robot_urdf/meshes/caster_link_right.STL" />
      </geometry>
      <material
        name="">
        <color
          rgba="0.79216 0.81961 0.93333 1" />
      </material>
    </visual>
    <collision>
      <origin
        xyz="0 0 0"
        rpy="0 0 0" />
      <geometry>
        <mesh
          filename="package://robot_urdf/meshes/caster_link_right.STL" />
      </geometry>
    </collision>
  </link>
  <joint
    name="caster_joint_right"
    type="fixed">
    <origin
      xyz="-0.077845 0.26812 0.1075"
      rpy="1.5708 0 0" />
    <parent
      link="base_link" />
    <child
      link="caster_link_right" />
    <axis
      xyz="0 -1 0" />
  </joint>
  <link
    name="caster_wheel_link_right">
    <inertial>
      <origin
        xyz="-0.015902 0 0.0017689"
        rpy="0 0 0" />
      <mass
        value="0.10698" />
      <inertia
        ixx="8.104E-05"
        ixy="-1.9527E-38"
        ixz="-3.9447E-06"
        iyy="4.558E-05"
        iyz="1.2422E-39"
        izz="4.6019E-05" />
    </inertial>
    <visual>
      <origin
        xyz="0 0 0"
        rpy="0 0 0" />
      <geometry>
        <mesh
          filename="package://robot_urdf/meshes/caster_wheel_link_right.STL" />
      </geometry>
      <material
        name="">
        <color
          rgba="0.79216 0.81961 0.93333 1" />
      </material>
    </visual>
    <collision>
      <origin
        xyz="0 0 0"
        rpy="0 0 0" />
      <geometry>
        <mesh
          filename="package://robot_urdf/meshes/caster_wheel_link_right.STL" />
      </geometry>
    </collision>
  </link>
  <joint
    name="caster_wheel_joint_right"
    type="continuous">
    <origin
      xyz="0.018657 -0.0675 0.023001"
      rpy="0 0 0" />
    <parent
      link="caster_link_right" />
    <child
      link="caster_wheel_link_right" />
    <axis
      xyz="0.99387 0 -0.11056" />
  </joint>
  <link
    name="drive_wheel_link_left">
    <inertial>
      <origin
        xyz="0.046034 0 0"
        rpy="0 0 0" />
      <mass
        value="0.55652" />
      <inertia
        ixx="0.0016491"
        ixy="-4.7815E-20"
        ixz="-9.7954E-21"
        iyy="0.00087192"
        iyz="3.3966E-20"
        izz="0.00087192" />
    </inertial>
    <visual>
      <origin
        xyz="0 0 0"
        rpy="0 0 0" />
      <geometry>
        <mesh
          filename="package://robot_urdf/meshes/drive_wheel_link_left.STL" />
      </geometry>
      <material
        name="">
        <color
          rgba="0.79216 0.81961 0.93333 1" />
      </material>
    </visual>
    <collision>
      <origin
        xyz="0 0 0"
        rpy="0 0 0" />
      <geometry>
        <mesh
          filename="package://robot_urdf/meshes/drive_wheel_link_left.STL" />
      </geometry>
    </collision>
  </link>
  <joint
    name="drive_wheel_joint_left"
    type="continuous">
    <origin
      xyz="0.10215 -0.15188 0.08"
      rpy="1.5708 0 0" />
    <parent
      link="base_link" />
    <child
      link="drive_wheel_link_left" />
    <axis
      xyz="1 0 0" />
  </joint>
  <link
    name="drive_wheel_link_right">
    <inertial>
      <origin
        xyz="-0.046034 0 0"
        rpy="0 0 0" />
      <mass
        value="0.55652" />
      <inertia
        ixx="0.0016491"
        ixy="-4.0348E-20"
        ixz="4.2297E-21"
        iyy="0.00087192"
        iyz="5.4077E-20"
        izz="0.00087192" />
    </inertial>
    <visual>
      <origin
        xyz="0 0 0"
        rpy="0 0 0" />
      <geometry>
        <mesh
          filename="package://robot_urdf/meshes/drive_wheel_link_right.STL" />
      </geometry>
      <material
        name="">
        <color
          rgba="0.79216 0.81961 0.93333 1" />
      </material>
    </visual>
    <collision>
      <origin
        xyz="0 0 0"
        rpy="0 0 0" />
      <geometry>
        <mesh
          filename="package://robot_urdf/meshes/drive_wheel_link_right.STL" />
      </geometry>
    </collision>
  </link>
  <joint
    name="drive_wheel_joint_right"
    type="continuous">
    <origin
      xyz="-0.10785 -0.15188 0.08"
      rpy="1.5708 0 0" />
    <parent
      link="base_link" />
    <child
      link="drive_wheel_link_right" />
    <axis
      xyz="1 0 0" />
  </joint>

</robot>